Workbook
Name apartmentcnt: 'MF Overview'!$W$30
Name inp_557ratio: 'MF Unit Material'!$AK$31
Name inp_boxlab: 'MF Unit Material'!$AJ$63
Name inp_caulkratio: 'MF Unit Material'!$AK$30
Name inp_condlen: 'MF Unit Material'!$AK$20
Name inp_cuwaste: 'MF Unit Material'!$AK$24
Name inp_dbtaperatio: 'MF Unit Material'!$AK$28
Name inp_dbwaste: 'MF Unit Material'!$AK$25
Name Inp_ductboardlab: 'MF Unit Material'!$AJ$61
Name inp_ductbrdsize: 'MF Unit Material'!$AK$26
Name inp_firecaulkratio: 'MF Unit Material'!$AK$29
Name inp_fittings: 'MF Unit Material'!$AK$21
Name inp_flexlabor: 'MF Unit Material'!$AJ$62
Name inp_flextaperatio: 'MF Unit Material'!$AK$35
Name inp_floors: 'MF Overview'!$O$35
Name inp_grillslab: 'MF Unit Material'!$AJ$64
Name inp_labdry: 'MF Unit Material'!$AJ$55
Name inp_labexh: 'MF Unit Material'!$AJ$54
Name inp_labpatio: 'MF Unit Material'!$AJ$56
Name inp_labpen: 'MF Unit Material'!$AJ$57
Name inp_labpipe: 'MF Pricing'!$AG$13
Name inp_labpipe: 'MF Unit Material'!$AJ$58
Name inp_loglabor: 'MF Unit Material'!$AJ$67
Name inp_metstrap: 'MF Unit Material'!$AK$23
Name inp_pookratio: 'MF Unit Material'!$AK$27
Name inp_statdist: 'MF Unit Material'!$AK$22
Name inp_statwire: 'MF Unit Material'!$AK$34
Name inp_unitlaborrough: 'MF Unit Material'!$AJ$50
Name inp_unitlabstart: 'MF Unit Material'!$AJ$51
Name inp_UVtaperatio: 'MF Unit Material'!$AK$32
Name inp_warrlab: 'MF Unit Material'!$AJ$68
Name Max_Width__Inch: [1]Data!$Q$34:$Q$38

Sheet Summary
C3: Job Sector | D3: Commercial | E3: Reduces the tax rate to 1/2%
C4: Margin | D4: M | E4: Selection of the margin rate (Low, Medium, High)
C5: Quick Turn | D5: n | E5: Reserved for public school jobs that must be completed in the summer months while school is in recession. Increases labor by 40%. Should be set to "n" in most cases
C6: Region | D6: Houston | E6: Region as identified in the proposal summary
D7: =INDEX($W$10:$W$18,MATCH($D$6,$V$10:$V$18,0),1) -> 1 | E7: Multiplier to increase/decrease labor rate for different regions. Basis of "1" is calibrated to Houston
C9: Schedule | D9: Materials Cost | E9: Labor Cost | F9: Mat. + Labor | G9: Cost/Ton (Mat) | H9: Cost/Ton (Labor) | I9: Cost/Ton (Mat+Labor) | J9: Split | K9: Updt | M9: Cooling Capacity | N9: ='Unit Sched'!D12 -> 0 | O9: tons | R9: Type | S9: Margin | T9: Quick Turn | V9: Area | W9: Labor Multiplier
C10: General | D10: =General!C14 -> 2592.5 | E10: =General!D14 -> 0 | F10: =SUM(D10:E10) -> 2592.5 | G10: =IFERROR(D10/$N$9,0) -> 0 | H10: =IFERROR(E10/$N$9,0) -> 0 | I10: =H10+G10 -> 0 | J10: =IFERROR(I10/$I$23,"") | R10: Commercial | S10: L | T10: y | V10: West | W10: 1.1
C11: Unit | D11: ='Unit Sched'!G12 -> 0 | E11: ='Unit Sched'!H12 -> 0 | F11: =SUM(D11:E11) -> 0 | G11: =IFERROR(D11/$N$9,0) -> 0 | H11: =IFERROR(E11/$N$9,0) -> 0 | I11: =H11+G11 -> 0 | J11: =IFERROR(I11/$I$23,"") | M11: Mercury Operations Cost Based Profit Calculator ( f(Labor) ) | R11: Public | S11: M | T11: n | V11: San Antonio | W11: 1
C12: CW Pipe | D12: ='CW Pipe Sched'!O413 -> 0 | E12: ='CW Pipe Sched'!R413 -> 0 | F12: =SUM(D12:E12) -> 0 | G12: =IFERROR(D12/$N$9,0) -> 0 | H12: =IFERROR(E12/$N$9,0) -> 0 | I12: =H12+G12 -> 0 | J12: =IFERROR(I12/$I$23,"") | M12: Boundaries | N12: Variable | O12: Pre- Tax | P12: Notes | R12: Multi Family | S12: H | V12: Austin | W12: 1.15
C13: VAV | D13: ='VAV Schedule'!L37 -> 0 | E13: ='VAV Schedule'!M37 -> 0 | F13: =SUM(D13:E13) -> 0 | G13: =IFERROR(D13/$N$9,0) -> 0 | H13: =IFERROR(E13/$N$9,0) -> 0 | I13: =H13+G13 -> 0 | J13: =IFERROR(I13/$I$23,"") | M13: Target EOY Net | N13: 0.1 | P13: Target end of year profitability | V13: DFW | W13: 1.1
C14: Heater | D14: ='Electric Heat Sched'!G24 -> 0 | E14: ='Electric Heat Sched'!H24 -> 0 | F14: =SUM(D14:E14) -> 0 | G14: =IFERROR(D14/$N$9,0) -> 0 | H14: =IFERROR(E14/$N$9,0) -> 0 | I14: =H14+G14 -> 0 | J14: =IFERROR(I14/$I$23,"") | M14: Overhead Variable | N14: 0.5 | P14: Overhead that functions based on project size | V14: Houston | W14: 1
C15: Fan | D15: ='Fan Schedule'!M30 -> 0 | E15: ='Fan Schedule'!P30 -> 0 | F15: =SUM(D15:E15) -> 0 | G15: =IFERROR(D15/$N$9,0) -> 0 | H15: =IFERROR(E15/$N$9,0) -> 0 | I15: =H15+G15 -> 0 | J15: =IFERROR(I15/$I$23,"") | M15: Overhead Fixed | N15: =INDEX($R$17:$R$43,MATCH($E$23,$T$17:$T$43,1)) -> 1000 | P15: Fixed overhead component ($2,900 per model) | V15: Panhandle | W15: 1.1
C16: Louver / Fire Damper | D16: ='Louvers & FD'!M30+'Louvers & FD'!M75 -> 0 | E16: ='Louvers & FD'!P30+'Louvers & FD'!P75 -> 0 | F16: =SUM(D16:E16) -> 0 | G16: =IFERROR(D16/$N$9,0) -> 0 | H16: =IFERROR(E16/$N$9,0) -> 0 | I16: =H16+G16 -> 0 | J16: =IFERROR(I16/$I$23,"") | M16: L | N16: -0.02 | R16: "Fixed" Overhead | S16: Gross Sale | T16: Labor Est | V16: South Texas | W16: 0.9
C17: Metal Duct | D17: ='Metal Duct'!W754+'Unit Sched'!J12 -> 0 | E17: ='Metal Duct'!X754+'Unit Sched'!K12 -> 0 | F17: =SUM(D17:E17) -> 0 | G17: =IFERROR(D17/$N$9,0) -> 0 | H17: =IFERROR(E17/$N$9,0) -> 0 | I17: =H17+G17 -> 0 | J17: =IFERROR(I17/$I$23,"") | M17: M | N17: 0 | R17: 1000 | S17: 0 | T17: 0 | V17: East Texas | W17: 1.1
C18: Diffusers | D18: ='Diffuser Schedule'!L24 -> 0 | E18: ='Diffuser Schedule'!M24 -> 0 | F18: =SUM(D18:E18) -> 0 | G18: =IFERROR(D18/$N$9,0) -> 0 | H18: =IFERROR(E18/$N$9,0) -> 0 | I18: =H18+G18 -> 0 | J18: =IFERROR(I18/$I$23,"") | M18: H | N18: 0.02 | R18: 1000 | S18: 10000 | T18: =S18*0.35 -> 3500 | V18: North Texas | W18: 1.1
C19: MF Living Units | F19: =SUM(D19:E19) -> 0 | G19: =IFERROR(D19/$N$9,0) -> 0 | H19: =IFERROR(E19/$N$9,0) -> 0 | I19: =H19+G19 -> 0 | J19: =IFERROR(I19/$I$23,"") | M19: Total Adj | N19: =INDEX($N$16:$N$18,MATCH($D$4,$M$16:$M$18,0),1)+N13 -> 0.1 | R19: 1100 | S19: 15000 | T19: =S19*0.35 -> 5250
C20: MF Common Area Duct Board / Flex | F20: =SUM(D20:E20) -> 0 | G20: =IFERROR(D20/$N$9,0) -> 0 | H20: =IFERROR(E20/$N$9,0) -> 0 | I20: =H20+G20 -> 0 | J20: =IFERROR(I20/$I$23,"") | M20: +Fixed | N20: =N15 -> 1000 | R20: 1200 | S20: 25000 | T20: =S20*0.35 -> 8750
C21: Labor Scalers | R21: 1300 | S21: 50000 | T21: =S21*0.3 -> 15000
C22: Quick Turn | M22: Base Profit Calculator | R22: 1350 | S22: 70000 | T22: =S22*0.3 -> 21000
C23: Base Schedule Total | D23: =SUM(D10:D20) -> 2592.5 | E23: =IF($D$5="y",1.4,1)*SUM(E10:E20)*$D$7 -> 0 | F23: =SUM(D23:E23) -> 2592.5 | G23: =SUM(G10:G20) -> 0 | H23: =SUM(H10:H20) -> 0 | I23: =SUM(I10:I20) -> 0 | M23: Boundaries | N23: Variable | O23: Pre- Tax | P23: Notes | R23: 1400 | S23: =S24-10000 -> 80000 | T23: =S23*0.3 -> 24000
M24: Min Labor Mult | N24: 0.8 | O24: =ROUND(D23+(1+N24)*E23,-2) -> 2600 | P24: Min allowable labor multiple in all scenarios | R24: =R23+100 -> 1500 | S24: =S25-10000 -> 90000 | T24: =S24*0.3 -> 27000
C25: Base Cost Breakout | D25: Materials | E25: Labor | M25: Max Labor Mult | N25: 2.5 | O25: =ROUND(D23+(1+N25)*E23,-2) -> 2600 | P25: Maximum labor multiplier for projects with mostly equipment | R25: =R24+100 -> 1600 | S25: =S26-10000 -> 100000 | T25: =S25*0.27 -> 27000
C26: Split | D26: =D23/$F$23 -> 1 | E26: =E23/$F$23 -> 0 | M26: L | N26: 0.18 | O26: =ROUND($F$23/(1-N26),-2) -> 3200 | P26: Preselected low profit margin | R26: =R25+100 -> 1700 | S26: =S27-10000 -> 110000 | T26: =S26*0.27 -> 29700
M27: M | N27: 0.2 | O27: =ROUND($F$23/(1-N27),-2) -> 3200 | P27: Preselected medium profit margin | R27: =R26+100 -> 1800 | S27: =S28-10000 -> 120000 | T27: =S27*0.27 -> 32400
C28: Mercury Operations Profit Calculator | E28: Price/Ton | G28: Tax Rates | M28: H | N28: 0.22 | O28: =ROUND($F$23/(1-N28),-2) -> 3300 | P28: Preselected high profit margin | R28: =R27+100 -> 1900 | S28: =S29-10000 -> 130000 | T28: =S28*0.27 -> 35100
C29: Bid | D29: =(($N$20+$E$23*$N$14)+$F$23)/(1-$N$19)+IF($D$3="Public",0.005*$D23,0) -> 3991.6667 | E29: =D29/$N$9 -> #DIV/0! | G29: Tax on Materials | H29: =IF(D3="Public",0,0.0825) -> 0.0825 | M29: 75000 | N29: =IF($F$23>M29,0,IF($F$23>=M30,1%,0)) -> 0 | R29: =R28+100 -> 2000 | S29: =S30-10000 -> 140000 | T29: =S29*0.27 -> 37800
C30: Gross Profit | D30: =D29-F23 -> 1399.1667 | E30: =D30/$N$9 -> #DIV/0! | G30: Tax on Labor | H30: 0 | M30: 50000 | N30: =IF(SUM(N$29:N29)>0,0,IF($F$23>M30,0,IF($F$23>=M31,2%,0))) -> 0 | R30: =R29+100 -> 2100 | S30: =S31-10000 -> 150000 | T30: =S30*0.25 -> 37500
C31: Margin | D31: =D30/D29 -> 0.35052192 | M31: 25000 | N31: =IF(SUM(N$29:N30)>0,0,IF($F$23>M31,0,IF($F$23>=M32,3%,0))) -> 0 | R31: =R30+100 -> 2200 | S31: =S32-10000 -> 160000 | T31: =S31*0.25 -> 40000
C32: Tax | D32: =ROUND(D23*($H$29)+E23*($H$30),-1) -> 210 | M32: 15000 | N32: =IF(SUM(N$29:N31)>0,0,IF($F$23>M32,0,IF($F$23>=M33,5%,0))) -> 0 | R32: =R31+100 -> 2300 | S32: =S33-10000 -> 170000 | T32: =S32*0.25 -> 42500
C33: Bid + Tax | D33: =D29+D32 -> 4201.6667 | M33: 10000 | N33: =IF(SUM(N$29:N32)>0,0,IF($F$23>M33,0,IF($F$23>=M34,9%,0))) -> 0 | R33: =R32+100 -> 2400 | S33: =S34-10000 -> 180000 | T33: =S33*0.25 -> 45000
C34: Note: 0.5% added for non-profit jobs to cover tax on materials | M34: 5000 | N34: =IF(SUM(N$29:N33)>0,0,IF($F$23>M34,0,IF($F$23>0,12%,0))) -> 0.12 | R34: =R33+100 -> 2500 | S34: =S35-10000 -> 190000 | T34: =S34*0.25 -> 47500
M35: Public Add | N35: =IF(D3="Public",5%,0) -> 0 | R35: =R34+100 -> 2600 | S35: =S36-10000 -> 200000 | T35: =S35*0.25 -> 50000
C36: Base Profit Calculator | E36: Price/Ton | M36: Labor Add | N36: =MAX(0,E26-0.25)*0.75 -> 0 | R36: =R35+100 -> 2700 | S36: =S37-10000 -> 210000 | T36: =S36*0.25 -> 52500
C37: Bid | D37: =O40+IF($D$3="Public",0.005*$D23,0) -> 2600 | E37: =D37/$N$9 -> #DIV/0! | M37: Total Add | N37: =SUM(N29:N36) -> 0.12 | R37: =R36+100 -> 2800 | S37: =S38-10000 -> 220000 | T37: =S37*0.25 -> 55000
C38: Gross Profit | D38: =D37-F23 -> 7.5 | E38: =D38/$N$9 -> #DIV/0! | M38: Base | N38: =INDEX($N$26:$N$28,MATCH($D$4,$M$26:$M$28,0),1) -> 0.2 | R38: =R37+100 -> 2900 | S38: =S39-10000 -> 230000 | T38: =S38*0.25 -> 57500
C39: Margin | D39: =D38/D37 -> 0.0028846154 | M39: Base + Add | N39: =SUM(N37:N38) -> 0.32 | O39: =ROUND($F$23/(1-N39),-2) -> 3800 | P39: Selected Margin | R39: =R38+100 -> 3000 | S39: =S40-10000 -> 240000 | T39: =S39*0.25 -> 60000
C40: Tax | D40: =ROUND(D23*($H$29)+E23*($H$30),-1) -> 210 | M40: Final w/ Boundaries | O40: =MIN(MAX(O39,O24),O25) -> 2600 | R40: =R39+100 -> 3100 | S40: 250000 | T40: =S40*0.25 -> 62500
C41: Bid + Tax | D41: =D37+D40 -> 2810 | R41: =R40+100 -> 3200 | S41: 2000000 | T41: =S41*0.25 -> 500000
C42: Note: 0.5% added for non-profit jobs to cover tax on materials | R42: 4000 | S42: 4000000 | T42: =S42*0.25 -> 1000000
R43: 6000 | S43: 6000000 | T43: =S43*0.25 -> 1500000
...

Sheet OverheadCalculator
B2: Commercial Construction Overhead Calculator Summary | J2: Commercial Construction Overhead Calculator Summary (Calculated to Labor instead of Sales) | R2: Testing
C3: Component | D3: Fixed | E3: Var. (H) | F3: Var. (L) | K3: Component | L3: Fixed | M3: Var. (H) | N3: Var. (L) | S3: 1000000 | T3: =S3+1000000 -> 2000000 | U3: =T3+1000000 -> 3000000 | V3: =U3+1000000 -> 4000000 | W3: =V3+1000000 -> 5000000 | X3: =W3+1000000 -> 6000000 | Y3: =X3+1000000 -> 7000000 | Z3: =Y3+1000000 -> 8000000 | AA3: =Z3+1000000 -> 9000000 | AB3: =AA3+1000000 -> 10000000 | AC3: <<<<Sales Rate
C4: President | E4: 0.01 | F4: 0.01 | K4: President | M4: =K17 -> 0.04 | N4: =K17 -> 0.04 | S4: =AVERAGE($M4:$N4)*(S$3/4) -> 10000 | T4: =AVERAGE($M4:$N4)*(T$3/4) -> 20000 | U4: =AVERAGE($M4:$N4)*(U$3/4) -> 30000 | V4: =AVERAGE($M4:$N4)*(V$3/4) -> 40000 | W4: =AVERAGE($M4:$N4)*(W$3/4) -> 50000 | X4: =AVERAGE($M4:$N4)*(X$3/4) -> 60000 | Y4: =AVERAGE($M4:$N4)*(Y$3/4) -> 70000 | Z4: =AVERAGE($M4:$N4)*(Z$3/4) -> 80000 | ... AB4: =AVERAGE($M4:$N4)*(AB$3/4) -> 100000
C5: Project Manager | D5: =C33 -> 2884 | E5: =C38 -> 0.02625 | F5: =52500/3000000 -> 0.0175 | K5: Project Manager | L5: =K33 -> 2884 | M5: =K38 -> 0.105 | N5: =M5*0.65 -> 0.06825 | S5: =AVERAGE($M5:$N5)*(S$3/4) -> 21656.25 | T5: =AVERAGE($M5:$N5)*(T$3/4) -> 43312.5 | U5: =AVERAGE($M5:$N5)*(U$3/4) -> 64968.75 | V5: =AVERAGE($M5:$N5)*(V$3/4) -> 86625 | W5: =AVERAGE($M5:$N5)*(W$3/4) -> 108281.25 | X5: =AVERAGE($M5:$N5)*(X$3/4) -> 129937.5 | Y5: =AVERAGE($M5:$N5)*(Y$3/4) -> 151593.75 | Z5: =AVERAGE($M5:$N5)*(Z$3/4) -> 173250 | ... AB5: =AVERAGE($M5:$N5)*(AB$3/4) -> 216562.5
C6: Field Supervisor | E6: =C47 -> 0.0325 | F6: =C45/3000000 -> 0.021666667 | K6: Field Supervisor | M6: =K47 -> 0.13 | N6: =M6*0.65 -> 0.0845 | S6: =AVERAGE($M6:$N6)*(S$3/4) -> 26812.5 | T6: =AVERAGE($M6:$N6)*(T$3/4) -> 53625 | U6: =AVERAGE($M6:$N6)*(U$3/4) -> 80437.5 | V6: =AVERAGE($M6:$N6)*(V$3/4) -> 107250 | W6: =AVERAGE($M6:$N6)*(W$3/4) -> 134062.5 | X6: =AVERAGE($M6:$N6)*(X$3/4) -> 160875 | Y6: =AVERAGE($M6:$N6)*(Y$3/4) -> 187687.5 | Z6: =AVERAGE($M6:$N6)*(Z$3/4) -> 214500 | ... AB6: =AVERAGE($M6:$N6)*(AB$3/4) -> 268125
C7: Human Resources | E7: =C58 -> 0.008 | F7: =48000/8000000 -> 0.006 | K7: Human Resources | M7: =K58 -> 0.024 | N7: =M7*0.65 -> 0.0156 | S7: =AVERAGE($M7:$N7)*(S$3/4) -> 4950 | T7: =AVERAGE($M7:$N7)*(T$3/4) -> 9900 | U7: =AVERAGE($M7:$N7)*(U$3/4) -> 14850 | V7: =AVERAGE($M7:$N7)*(V$3/4) -> 19800 | W7: =AVERAGE($M7:$N7)*(W$3/4) -> 24750 | X7: =AVERAGE($M7:$N7)*(X$3/4) -> 29700 | Y7: =AVERAGE($M7:$N7)*(Y$3/4) -> 34650 | Z7: =AVERAGE($M7:$N7)*(Z$3/4) -> 39600 | ... AB7: =AVERAGE($M7:$N7)*(AB$3/4) -> 49500
C8: Estimation | E8: =C69 -> 0.02 | F8: =20000/1500000 -> 0.013333333 | K8: Estimation | M8: =K69 -> 0.08 | N8: =M8*0.65 -> 0.052 | S8: =AVERAGE($M8:$N8)*(S$3/4) -> 16500 | T8: =AVERAGE($M8:$N8)*(T$3/4) -> 33000 | U8: =AVERAGE($M8:$N8)*(U$3/4) -> 49500 | V8: =AVERAGE($M8:$N8)*(V$3/4) -> 66000 | W8: =AVERAGE($M8:$N8)*(W$3/4) -> 82500 | X8: =AVERAGE($M8:$N8)*(X$3/4) -> 99000 | Y8: =AVERAGE($M8:$N8)*(Y$3/4) -> 115500 | Z8: =AVERAGE($M8:$N8)*(Z$3/4) -> 132000 | ... AB8: =AVERAGE($M8:$N8)*(AB$3/4) -> 165000
C9: Rent/Office | E9: =C81 -> 0.0186 | F9: =37200/3000000 -> 0.0124 | K9: Rent/Office | M9: =K81 -> 0.0744 | N9: =M9*0.65 -> 0.04836 | S9: =AVERAGE($M9:$N9)*(S$3/4) -> 15345 | T9: =AVERAGE($M9:$N9)*(T$3/4) -> 30690 | U9: =AVERAGE($M9:$N9)*(U$3/4) -> 46035 | V9: =AVERAGE($M9:$N9)*(V$3/4) -> 61380 | W9: =AVERAGE($M9:$N9)*(W$3/4) -> 76725 | X9: =AVERAGE($M9:$N9)*(X$3/4) -> 92070 | Y9: =AVERAGE($M9:$N9)*(Y$3/4) -> 107415 | Z9: =AVERAGE($M9:$N9)*(Z$3/4) -> 122760 | ... AB9: =AVERAGE($M9:$N9)*(AB$3/4) -> 153450
C10: Insurance & Services | E10: =C95 -> 0.015 | F10: =30000/3000000 -> 0.01 | K10: Insurance & Services | M10: =K95 -> 0.06 | N10: =M10*0.65 -> 0.039 | S10: =AVERAGE($M10:$N10)*(S$3/4) -> 12375 | T10: =AVERAGE($M10:$N10)*(T$3/4) -> 24750 | U10: =AVERAGE($M10:$N10)*(U$3/4) -> 37125 | V10: =AVERAGE($M10:$N10)*(V$3/4) -> 49500 | W10: =AVERAGE($M10:$N10)*(W$3/4) -> 61875 | X10: =AVERAGE($M10:$N10)*(X$3/4) -> 74250 | Y10: =AVERAGE($M10:$N10)*(Y$3/4) -> 86625 | Z10: =AVERAGE($M10:$N10)*(Z$3/4) -> 99000 | ... AB10: =AVERAGE($M10:$N10)*(AB$3/4) -> 123750
C11: Total | D11: =ROUND(SUM(D4:D10),-2) -> 2900 | E11: =SUM(E4:E10) -> 0.13035 | F11: =SUM(F4:F10) -> 0.0909 | K11: Total | L11: =ROUND(SUM(L4:L10),-2) -> 2900 | M11: =SUM(M4:M10) -> 0.5134 | N11: =SUM(N4:N10) -> 0.34771
S12: Project Managers
S13: 1 | T13: 1 | U13: 1 | V13: 1 | W13: 1 | X13: 1 | Y13: 1 | Z13: 1 | AA13: 1 | AB13: 1
S14: =S4/S13 -> 10000 | T14: =T4/T13 -> 20000 | U14: =U4/U13 -> 30000 | V14: =V4/V13 -> 40000 | W14: =W4/W13 -> 50000 | X14: =X4/X13 -> 60000 | Y14: =Y4/Y13 -> 70000 | Z14: =Z4/Z13 -> 80000 | ... AB14: =AB4/AB13 -> 100000 | AC14: <<<<Calc Avg Salary
B15: President Calculator | J15: President Calculator | S15: 70000 | T15: 70000 | U15: 70000 | V15: 70000 | W15: 70000 | X15: 70000 | Y15: 70000 | Z15: 70000 | AA15: 70000 | AB15: 70000 | AC15: <<<<Act Avg Salary
C16: Rate | D16: Notes | K16: Rate | L16: Notes | S16: =S15*S13-S14*S13 -> 60000 | T16: =T15*T13-T14*T13 -> 50000 | U16: =U15*U13-U14*U13 -> 40000 | V16: =V15*V13-V14*V13 -> 30000 | W16: =W15*W13-W14*W13 -> 20000 | X16: =X15*X13-X14*X13 -> 10000 | Y16: =Y15*Y13-Y14*Y13 -> 0 | Z16: =Z15*Z13-Z14*Z13 -> -10000 | ... AB16: =AB15*AB13-AB14*AB13 -> -30000 | AC16: Net Delta
C17: 0.01 | D17: Assumed pay rate relative to gross sales | K17: 0.04 | L17: Assumed pay rate relative to gross sales
B19: Project Manager Calculator | J19: Project Manager Calculator | S19: Project Managers
C20: Notes: | K20: Notes: | S20: 1 | T20: 1 | U20: 1 | V20: 2 | W20: 2 | X20: 2 | Y20: 3 | Z20: 3 | AA20: 3 | AB20: 4
D21: - It was determined that a PM can handle about $2MM of work across 8 projects | L21: - It was determined that a PM can handle about $500k of labor cost across 8 projects | S21: =S5/S20 -> 21656.25 | T21: =T5/T20 -> 43312.5 | U21: =U5/U20 -> 64968.75 | V21: =V5/V20 -> 43312.5 | W21: =W5/W20 -> 54140.625 | X21: =X5/X20 -> 64968.75 | Y21: =Y5/Y20 -> 50531.25 | Z21: =Z5/Z20 -> 57750 | ... AB21: =AB5/AB20 -> 54140.625 | AC21: <<<<Calc Avg Salary
D22: - Based on that it's estimated that there is a 1) fixed labor component independent of project size | L22: - Based on that it's estimated that there is a 1) fixed labor component independent of project size | S22: 65000 | T22: 65000 | U22: 65000 | V22: 65000 | W22: 65000 | X22: 65000 | Y22: 65000 | Z22: 65000 | AA22: 65000 | AB22: 65000 | AC22: <<<<Act Avg Salary
D23: - 2) variable for scheduling, sheet metal duct ordering, invoicing, and related | L23: - 2) variable for scheduling, sheet metal duct ordering, invoicing, and related | S23: =S22*S20-S21*S20 -> 43343.75 | T23: =T22*T20-T21*T20 -> 21687.5 | U23: =U22*U20-U21*U20 -> 31.25 | V23: =V22*V20-V21*V20 -> 43375 | W23: =W22*W20-W21*W20 -> 21718.75 | X23: =X22*X20-X21*X20 -> 62.5 | Y23: =Y22*Y20-Y21*Y20 -> 43406.25 | Z23: =Z22*Z20-Z21*Z20 -> 21750 | ... AB23: =AB22*AB20-AB21*AB20 -> 43437.5 | AC23: Net Delta
D24: - Calculations are based on an assumed income of $75,000/yr for a project manager | L24: - Calculations are based on an assumed income of $75,000/yr for a project manager
D25: - Weekly PM cost is assumed to be: $1,442 ($75k/yr) | L25: - Weekly PM cost is assumed to be: $1,442 ($75k/yr) | S25: Field Supervisor
D26: - Based on our experience and assumptions above, we believe ~30% relates to a fixed per project cost and ~70% is a function of project size (variable) | L26: - Based on our experience and assumptions above, we believe ~30% relates to a fixed per project cost and ~70% is a function of project size (variable) | S26: 1 | T26: 1 | U26: 1 | V26: 2 | W26: 2 | X26: 2 | Y26: 3 | Z26: 3 | AA26: 3 | AB26: 4
D27: - 70% of a PM's pay of $75k/yr = $52,500 | L27: - 70% of a PM's pay of $75k/yr = $52,500 | S27: =S6/S26 -> 26812.5 | T27: =T6/T26 -> 53625 | U27: =U6/U26 -> 80437.5 | V27: =V6/V26 -> 53625 | W27: =W6/W26 -> 67031.25 | X27: =X6/X26 -> 80437.5 | Y27: =Y6/Y26 -> 62562.5 | Z27: =Z6/Z26 -> 71500 | ... AB27: =AB6/AB26 -> 67031.25 | AC27: <<<<Calc Avg Salary
C28: Fixed Time Components | K28: Fixed Time Components | S28: 70000 | T28: 70000 | U28: 70000 | V28: 70000 | W28: 70000 | X28: 70000 | Y28: 70000 | Z28: 70000 | AA28: 70000 | AB28: 70000 | AC28: <<<<Act Avg Salary
C29: Weeks | D29: Description | K29: Weeks | L29: Description | S29: =S28*S26-S27*S26 -> 43187.5 | T29: =T28*T26-T27*T26 -> 16375 | U29: =U28*U26-U27*U26 -> -10437.5 | V29: =V28*V26-V27*V26 -> 32750 | W29: =W28*W26-W27*W26 -> 5937.5 | X29: =X28*X26-X27*X26 -> -20875 | Y29: =Y28*Y26-Y27*Y26 -> 22312.5 | Z29: =Z28*Z26-Z27*Z26 -> -4500 | ... AB29: =AB28*AB26-AB27*AB26 -> 11875 | AC29: Net Delta
C30: =8/5 -> 1.6 | D30: Private | G30: Fixed: Onboarding paperwork, Permits, Submittals, Equipment Orders, Rentals, & Closind Docs | K30: =8/5 -> 1.6 | L30: Private | O30: Fixed: Onboarding paperwork, Permits, Submittals, Equipment Orders, Rentals, & Closind Docs
C31: =12/5 -> 2.4 | D31: Public | G31: Fixed: Onboarding paperwork, Permits, Submittals, Equipment Orders, Rentals, & Closind Docs | K31: =12/5 -> 2.4 | L31: Public | O31: Fixed: Onboarding paperwork, Permits, Submittals, Equipment Orders, Rentals, & Closind Docs
C32: =(C31+C30)/2 -> 2 | D32: Average | G32: Predicted weeks of work associated with a project regardless of size | K32: =(K31+K30)/2 -> 2 | L32: Average | O32: Predicted weeks of work associated with a project regardless of size | S32: Human Resources
C33: =1442*C32 -> 2884 | D33: Fixed Project Cost based on weekly PM cost | K33: =1442*K32 -> 2884 | L33: Fixed Project Cost based on weekly PM cost | S33: 1 | T33: 1 | U33: 1 | V33: 1 | W33: 1 | X33: 1 | Y33: 1 | Z33: 1.5 | AA33: 1.5 | AB33: 1.5
C34: Variable Time Components | K34: Variable Time Components | S34: =S7/S33 -> 4950 | T34: =T7/T33 -> 9900 | U34: =U7/U33 -> 14850 | V34: =V7/V33 -> 19800 | W34: =W7/W33 -> 24750 | X34: =X7/X33 -> 29700 | Y34: =Y7/Y33 -> 34650 | Z34: =Z7/Z33 -> 26400 | ... AB34: =AB7/AB33 -> 33000 | AC34: <<<<Calc Avg Salary
C35: Metric | D35: Description | K35: Metric | L35: Description | S35: 45000 | T35: 45000 | U35: 45000 | V35: 45000 | W35: 45000 | X35: 45000 | Y35: 45000 | Z35: 45000 | AA35: 45000 | AB35: 45000 | AC35: <<<<Act Avg Salary
C36: 52500 | D36: Salary applicable to project size | K36: 52500 | L36: Salary applicable to project size | S36: =S35*S33-S34*S33 -> 40050 | T36: =T35*T33-T34*T33 -> 35100 | U36: =U35*U33-U34*U33 -> 30150 | V36: =V35*V33-V34*V33 -> 25200 | W36: =W35*W33-W34*W33 -> 20250 | X36: =X35*X33-X34*X33 -> 15300 | Y36: =Y35*Y33-Y34*Y33 -> 10350 | Z36: =Z35*Z33-Z34*Z33 -> 27900 | ... AB36: =AB35*AB33-AB34*AB33 -> 18000 | AC36: Net Delta
C37: 2000000 | D37: Assumed comfortable average limit for a project manager overseeing commercial projects (8 projects @ $250,000/project) | K37: 500000 | L37: Assumed comfortable average limit for a project manager overseeing commercial projects (8 projects @ $250,000/project)
C38: =C36/C37 -> 0.02625 | D38: Percentage of project related size (variable cost) | K38: =K36/K37 -> 0.105 | L38: Percentage of project related size (variable cost) | S38: Estimation Services
S39: 1 | T39: 1 | U39: 2 | V39: 2 | W39: 2 | X39: 3 | Y39: 3 | Z39: 3 | AA39: 4 | AB39: 4
B40: Field Supervisor Calculator | J40: Field Supervisor Calculator | S40: =S8/S39 -> 16500 | T40: =T8/T39 -> 33000 | U40: =U8/U39 -> 24750 | V40: =V8/V39 -> 33000 | W40: =W8/W39 -> 41250 | X40: =X8/X39 -> 33000 | Y40: =Y8/Y39 -> 38500 | Z40: =Z8/Z39 -> 44000 | ... AB40: =AB8/AB39 -> 41250 | AC40: <<<<Calc Avg Salary
C41: Notes: | D41: NOT SURE IF WE CAN HAVE A PURE FIELD SUPERVISOR. THIS COST NEEDS TO BE FOLDED INTO JOB LABOR CALCULATOR | K41: Notes: | L41: NOT SURE IF WE CAN HAVE A PURE FIELD SUPERVISOR. THIS COST NEEDS TO BE FOLDED INTO JOB LABOR CALCULATOR | S41: 12000 | T41: 12000 | U41: 12000 | V41: 12000 | W41: 12000 | X41: 12000 | Y41: 12000 | Z41: 12000 | AA41: 12000 | AB41: 12000 | AC41: <<<<Act Avg Salary
D42: - It is assumed that 1 field supervisor team member can handle $2,000,000 employees | L42: - It is assumed that 1 field supervisor team member can handle $2,000,000 employees | S42: =S41*S39-S40*S39 -> -4500 | T42: =T41*T39-T40*T39 -> -21000 | U42: =U41*U39-U40*U39 -> -25500 | V42: =V41*V39-V40*V39 -> -42000 | W42: =W41*W39-W40*W39 -> -58500 | X42: =X41*X39-X40*X39 -> -63000 | Y42: =Y41*Y39-Y40*Y39 -> -79500 | Z42: =Z41*Z39-Z40*Z39 -> -96000 | ... AB42: =AB41*AB39-AB40*AB39 -> -117000 | AC42: Net Delta
...

Sheet General
B1: =IF(Summary!$C$1="","",Summary!$C$1)
B2: General Items | G2: Defined Ranges (Don't erase)
B3: Item | C3: Materials Cost | D3: Labor Cost | E3: Notes | G3: Binary
B4: Permitting | C4: =C23 -> 192.5 | G4: Yes
B5: Field Logistics | D5: =D33 -> 0 | G5: No
B6: Crane Service | C6: =C48 -> 0
B7: Demolition | D7: =D68 -> 0
B8: Rentals | C8: =C82 -> 2400
B9: Air Balance | C9: =C94 -> 0
B10: Warranty | D10: =D104 -> 0
B11: Team Travel | C11: =C115 -> 0
B12: NA | C12: 0 | D12: 0
B13: NA | C13: 0 | D13: 0
B14: Totals | C14: =SUM(C4:C13) -> 2592.5 | D14: =SUM(D4:D13) -> 0
B16: Permitting
B17: Item | C17: Selection | E17: Description
B18: Required | C18: Yes | E18: Permit required aside from AC system changeouts or service
B19: Direct Job Cost | C19: =Summary!F18+Summary!F17+Summary!F15+Summary!F14+Summary!F13+Summary!F11+Summary!F12 -> 0 | E19: Total of direct field level labor and materials cost
B20: Base Cost ($) | C20: {=IF(C18="",_xludf.ISERROR,IF($C$18="yes",MAX(175,C19*0.005),0))} -> 175 | E20: Modeled as the maximum of 0.5% of project cost or $175
B21: Inc. Rate | C21: 0.1
B22: Inc ($) | C22: =C20*C21 -> 17.5
B23: Total Cost | C23: =C22+C20 -> 192.5
B25: Field Logistics | G25: Logisitics Calculator
B26: Item | D26: Selection | E26: Description | G26: Component | H26: Value
B27: Required | D27: Yes | E27: Required for all jobs currently | G27: Rate | H27: 45000 | I27: 70000
B28: Labor Total | D28: =Summary!$E$18+Summary!$E$17+Summary!$E$15+Summary!$E$14+Summary!$E$13+Summary!$E$11++Summary!$E$12 -> 0 | E28: Labor total from 'Summary' tab | G28: Job Gross | H28: 3000000 | I28: 2000000
B29: Field Logistics | D29: =H30 -> 0.06 | E29: Logistical rate for field support relative to direct labor. Assumed 5% in all cases | G29: Labor Est. | H29: =H28*0.25 -> 750000 | I29: =I28*0.25 -> 500000
B30: Base Cost ($) | D30: =IF(D27="Yes",D28*D29,0) -> 0 | E30: Modeled relative to field labor requirements | G30: Logistics Component | H30: =H27/H29 -> 0.06 | I30: =I27/I29 -> 0.14
B31: Inc. Rate | D31: 0 | E31: No incidental rate currently assumed
B32: Inc ($) | D32: =D30*D31 -> 0
B33: Total Cost | D33: =D32+D30 -> 0
B35: Crane Service (New Units) | G35: Crane Perameters (Don't erase)
B36: Item | C36: Selection | E36: Description | G36: Unit Category | H36: Desc | I36: Crane Size | J36: Price/Day
B37: Required | C37: No | E37: Required for all jobs currently | G37: Small | H37: <= 5 ton | I37: 19 | J37: 750
B38: Lifted Unit Count | C38: 5 | E38: Total number of units that will be lifted/unloaded by crane (1 for each new unit and 1 for each removed unit) | G38: Med | H38: <= 10 ton | I38: 40 | J38: 1500
B39: Extra Lift Days | C39: 0 | E39: Extra days required for logistics (1 for each additional day based on planned logistical schedule) | G39: Large | H39: <= 25 ton | I39: 80 | J39: 3500
B40: Largest Unit Category | C40: Max | G40: Max | H40: > 25 ton/chiller | I40: 120 | J40: 4500
B41: Largest Unit Desc | C41: =INDEX($H$37:$H$40,MATCH(C40,$G$37:$G$40,0),1) -> > 25 ton/chiller | E41: Unit size associated with "Largest Unit Category"
B42: Crane Size (tons) | C42: =INDEX($I$37:$I$40,MATCH(C40,$G$37:$G$40,0),1) -> 120 | E42: Crane size specified by "Largest Unit Category"
B43: Crane Cost/Day | C43: =INDEX($J$37:$J$40,MATCH(C40,$G$37:$G$40,0),1) -> 4500
...

Sheet Unit Sched
B1: =IF(Summary!$C$1="","",Summary!$C$1)
B2: Unit Summary | J2: Near Unit Duct Summary (Do not include this on Duct schedule)
C3: Type | D3: Cooling (Tons) | E3: Equip + Accessories ($) | F3: Misc. ($) | G3: Total Materials ($) | H3: Labor ($) | I3: Materials + Labor | J3: Materials | K3: Labor | L3: Materials + Labor | N3: Note: Need to add a selection for knockdown units (requires dissasembly to get into the building)
B4: 1 | C4: Service of Existing | D4: =D43 -> 0 | E4: 0 | F4: =F43 -> 0 | G4: =E4+F4 -> 0 | H4: =G43 -> 0 | I4: =G4+H4 -> 0 | J4: 0 | K4: 0 | L4: =SUM(J4:K4) -> 0
B5: 2 | C5: Package | D5: =D82 -> 0 | E5: =AD82+AE82 -> 0 | F5: =AF82 -> 0 | G5: =E5+F5 -> 0 | H5: =AW82 -> 0 | I5: =G5+H5 -> 0 | J5: =AH82 -> 0 | K5: =AZ82 -> 0 | L5: =SUM(J5:K5) -> 0
B6: 3 | C6: Standard Split | D6: =D111 -> 0 | E6: =AL111+AM111 -> 0 | F6: =AN111 -> 0 | G6: =E6+F6 -> 0 | H6: =BD111 -> 0 | I6: =G6+H6 -> 0 | J6: =AP111 -> 0 | K6: =BE111 -> 0 | L6: =SUM(J6:K6) -> 0
B7: 4 | C7: Wall Mounted Split | D7: =D140 -> 0 | E7: =Y140+Z140 -> 0 | F7: =AA140 -> 0 | G7: =E7+F7 -> 0 | H7: =AL140 -> 0 | I7: =G7+H7 -> 0 | J7: 0 | K7: 0 | L7: 0
B8: 5 | C8: VRF | D8: =D169 -> 0 | E8: =AD169+AE169 -> 0 | F8: =AF169 -> 0 | G8: =E8+F8 -> 0 | H8: =AS169 -> 0 | I8: =G8+H8 -> 0 | J8: 0 | K8: 0 | L8: 0
B9: 6 | C9: [FPB/VAV] | G9: =E9+F9 -> 0 | I9: =G9+H9 -> 0
B10: 7 | C10: [Chiller] | G10: =E10+F10 -> 0 | I10: =G10+H10 -> 0
B11: 8 | C11: Boilers | G11: =E11+F11 -> 0 | I11: =G11+H11 -> 0
D12: =SUM(D4:D11) -> 0 | E12: =SUM(E4:E11) -> 0 | F12: =SUM(F4:F11) -> 0 | G12: =SUM(G4:G11) -> 0 | H12: =SUM(H4:H11) -> 0 | I12: =SUM(I4:I11) -> 0 | J12: =SUM(J4:J11) -> 0 | K12: =SUM(K4:K11) -> 0 | L12: =SUM(L4:L11) -> 0
C13: Unit Count (Warranty) | D13: =COUNT($D$57:$D$81)+COUNT($D$86:$D$110)+COUNT($D$115:$D$139)+COUNT($D$144:$D$168) -> 0
C14: Unit Count (Air Balance) | D14: =COUNT($D$57:$D$81)+COUNT($D$86:$D$110)+COUNT($D$115:$D$139)+COUNT($D$144:$D$168)+COUNT($D$18:$D$42) -> 0
B16: Servicing of Existing Units | I16: Materials Cost | Q16: Labor | Z16: Unit Type
B17: Unit | C17: Name | D17: Cool (Tons) | E17: System Type | F17: PM Materials | G17: PM Labor | I17: System Type | J17: Packaged Unit | K17: Standard Split | L17: Wall Mount Split | M17: VRF | N17: VAV/FBP | O17: Chiller | P17: Boiler | Q17: System Type | R17: Packaged Unit | S17: Standard Split | T17: Wall Mount Split | U17: VRF | V17: VAV/FBP | W17: Chiller | X17: Boiler | Z17: Packaged Unit
B18: 1 | F18: =IF($D18="",0,IF($E18="",0,INDEX($J$19:$P$24,MATCH($D18,$I$19:$I$24,1),MATCH($E18,$J$17:$P$17,0)))) -> 0 | G18: =IF($D18="",0,IF($E18="",0,INDEX($R$19:$X$24,MATCH($D18,$I$19:$I$24,1),MATCH($E18,$R$17:$X$17,0)))) -> 0 | I18: Size | J18: Cost | K18: Cost | L18: Cost | M18: Cost | N18: Cost | O18: Cost | P18: Cost | Q18: Size | R18: Cost | S18: Cost | T18: Cost | U18: Cost | V18: Cost | W18: Cost | X18: Cost | Z18: Standard Split
B19: =B18+1 -> 2 | F19: =IF($D19="",0,IF($E19="",0,INDEX($J$19:$P$24,MATCH($D19,$I$19:$I$24,1),MATCH($E19,$J$17:$P$17,0)))) -> 0 | G19: =IF($D19="",0,IF($E19="",0,INDEX($R$19:$X$24,MATCH($D19,$I$19:$I$24,1),MATCH($E19,$R$17:$X$17,0)))) -> 0 | I19: 0 | J19: 150 | K19: 150 | L19: =K19*0.65 -> 97.5 | M19: 300 | N19: =M19*0.65 -> 195 | O19: 650 | P19: 300 | Q19: 0 | R19: 100 | S19: 100 | T19: 75 | U19: 400 | V19: 50 | W19: =400 -> 400 | X19: 400 | Z19: Wall Mount Split
B20: =B19+1 -> 3 | F20: =IF($D20="",0,IF($E20="",0,INDEX($J$19:$P$24,MATCH($D20,$I$19:$I$24,1),MATCH($E20,$J$17:$P$17,0)))) -> 0 | G20: =IF($D20="",0,IF($E20="",0,INDEX($R$19:$X$24,MATCH($D20,$I$19:$I$24,1),MATCH($E20,$R$17:$X$17,0)))) -> 0 | I20: 5 | J20: 150 | K20: 150 | L20: =K20*0.65 -> 97.5 | M20: 300 | N20: =M20*0.65 -> 195 | O20: 650 | P20: 300 | Q20: 5 | R20: 100 | S20: 100 | T20: 75 | U20: 400 | V20: 50 | W20: 400 | X20: 400 | Z20: VRF
B21: =B20+1 -> 4 | F21: =IF($D21="",0,IF($E21="",0,INDEX($J$19:$P$24,MATCH($D21,$I$19:$I$24,1),MATCH($E21,$J$17:$P$17,0)))) -> 0 | G21: =IF($D21="",0,IF($E21="",0,INDEX($R$19:$X$24,MATCH($D21,$I$19:$I$24,1),MATCH($E21,$R$17:$X$17,0)))) -> 0 | I21: 10 | J21: 175 | K21: 175 | L21: =K21*0.65 -> 113.75 | M21: 350 | N21: =M21*0.65 -> 227.5 | O21: 750 | P21: 350 | Q21: 10 | R21: 125 | S21: 125 | T21: 100 | U21: 500 | V21: 75 | W21: 600 | X21: 450 | Z21: VAV/FBP
B22: =B21+1 -> 5 | F22: =IF($D22="",0,IF($E22="",0,INDEX($J$19:$P$24,MATCH($D22,$I$19:$I$24,1),MATCH($E22,$J$17:$P$17,0)))) -> 0 | G22: =IF($D22="",0,IF($E22="",0,INDEX($R$19:$X$24,MATCH($D22,$I$19:$I$24,1),MATCH($E22,$R$17:$X$17,0)))) -> 0 | I22: 20 | J22: 175 | K22: 175 | L22: =K22*0.65 -> 113.75 | M22: 400 | N22: =M22*0.65 -> 260 | O22: 1200 | P22: 400 | Q22: 20 | R22: 200 | S22: 200 | T22: 150 | U22: 800 | V22: 125 | W22: 800 | X22: 600 | Z22: Chiller
B23: =B22+1 -> 6 | F23: =IF($D23="",0,IF($E23="",0,INDEX($J$19:$P$24,MATCH($D23,$I$19:$I$24,1),MATCH($E23,$J$17:$P$17,0)))) -> 0 | G23: =IF($D23="",0,IF($E23="",0,INDEX($R$19:$X$24,MATCH($D23,$I$19:$I$24,1),MATCH($E23,$R$17:$X$17,0)))) -> 0 | I23: 50 | J23: 250 | K23: 250 | L23: =K23*0.65 -> 162.5 | M23: 800 | N23: =M23*0.65 -> 520 | O23: 1500 | P23: 600 | Q23: 50 | R23: 400 | S23: 400 | T23: 250 | U23: 1000 | V23: 200 | W23: 1200 | X23: 800 | Z23: Boiler
B24: =B23+1 -> 7 | F24: =IF($D24="",0,IF($E24="",0,INDEX($J$19:$P$24,MATCH($D24,$I$19:$I$24,1),MATCH($E24,$J$17:$P$17,0)))) -> 0 | G24: =IF($D24="",0,IF($E24="",0,INDEX($R$19:$X$24,MATCH($D24,$I$19:$I$24,1),MATCH($E24,$R$17:$X$17,0)))) -> 0 | I24: 75 | J24: 350 | K24: 350 | L24: =K24*0.65 -> 227.5 | M24: 1500 | N24: =M24*0.65 -> 975 | O24: 2000 | P24: 800 | Q24: 75 | R24: 800 | S24: 800 | T24: 300 | U24: 1500 | V24: 300 | W24: 1600 | X24: 1200
B25: =B24+1 -> 8 | F25: =IF($D25="",0,IF($E25="",0,INDEX($J$19:$P$24,MATCH($D25,$I$19:$I$24,1),MATCH($E25,$J$17:$P$17,0)))) -> 0 | G25: =IF($D25="",0,IF($E25="",0,INDEX($R$19:$X$24,MATCH($D25,$I$19:$I$24,1),MATCH($E25,$R$17:$X$17,0)))) -> 0
B26: =B25+1 -> 9 | F26: =IF($D26="",0,IF($E26="",0,INDEX($J$19:$P$24,MATCH($D26,$I$19:$I$24,1),MATCH($E26,$J$17:$P$17,0)))) -> 0 | G26: =IF($D26="",0,IF($E26="",0,INDEX($R$19:$X$24,MATCH($D26,$I$19:$I$24,1),MATCH($E26,$R$17:$X$17,0)))) -> 0
B27: =B26+1 -> 10 | F27: =IF($D27="",0,IF($E27="",0,INDEX($J$19:$P$24,MATCH($D27,$I$19:$I$24,1),MATCH($E27,$J$17:$P$17,0)))) -> 0 | G27: =IF($D27="",0,IF($E27="",0,INDEX($R$19:$X$24,MATCH($D27,$I$19:$I$24,1),MATCH($E27,$R$17:$X$17,0)))) -> 0
B28: =B27+1 -> 11 | F28: =IF($D28="",0,IF($E28="",0,INDEX($J$19:$P$24,MATCH($D28,$I$19:$I$24,1),MATCH($E28,$J$17:$P$17,0)))) -> 0 | G28: =IF($D28="",0,IF($E28="",0,INDEX($R$19:$X$24,MATCH($D28,$I$19:$I$24,1),MATCH($E28,$R$17:$X$17,0)))) -> 0
B29: =B28+1 -> 12 | F29: =IF($D29="",0,IF($E29="",0,INDEX($J$19:$P$24,MATCH($D29,$I$19:$I$24,1),MATCH($E29,$J$17:$P$17,0)))) -> 0 | G29: =IF($D29="",0,IF($E29="",0,INDEX($R$19:$X$24,MATCH($D29,$I$19:$I$24,1),MATCH($E29,$R$17:$X$17,0)))) -> 0
B30: =B29+1 -> 13 | F30: =IF($D30="",0,IF($E30="",0,INDEX($J$19:$P$24,MATCH($D30,$I$19:$I$24,1),MATCH($E30,$J$17:$P$17,0)))) -> 0 | G30: =IF($D30="",0,IF($E30="",0,INDEX($R$19:$X$24,MATCH($D30,$I$19:$I$24,1),MATCH($E30,$R$17:$X$17,0)))) -> 0
B31: =B30+1 -> 14 | F31: =IF($D31="",0,IF($E31="",0,INDEX($J$19:$P$24,MATCH($D31,$I$19:$I$24,1),MATCH($E31,$J$17:$P$17,0)))) -> 0 | G31: =IF($D31="",0,IF($E31="",0,INDEX($R$19:$X$24,MATCH($D31,$I$19:$I$24,1),MATCH($E31,$R$17:$X$17,0)))) -> 0
B32: =B31+1 -> 15 | F32: =IF($D32="",0,IF($E32="",0,INDEX($J$19:$P$24,MATCH($D32,$I$19:$I$24,1),MATCH($E32,$J$17:$P$17,0)))) -> 0 | G32: =IF($D32="",0,IF($E32="",0,INDEX($R$19:$X$24,MATCH($D32,$I$19:$I$24,1),MATCH($E32,$R$17:$X$17,0)))) -> 0
B33: =B32+1 -> 16 | F33: =IF($D33="",0,IF($E33="",0,INDEX($J$19:$P$24,MATCH($D33,$I$19:$I$24,1),MATCH($E33,$J$17:$P$17,0)))) -> 0 | G33: =IF($D33="",0,IF($E33="",0,INDEX($R$19:$X$24,MATCH($D33,$I$19:$I$24,1),MATCH($E33,$R$17:$X$17,0)))) -> 0
B34: =B33+1 -> 17 | F34: =IF($D34="",0,IF($E34="",0,INDEX($J$19:$P$24,MATCH($D34,$I$19:$I$24,1),MATCH($E34,$J$17:$P$17,0)))) -> 0 | G34: =IF($D34="",0,IF($E34="",0,INDEX($R$19:$X$24,MATCH($D34,$I$19:$I$24,1),MATCH($E34,$R$17:$X$17,0)))) -> 0
B35: =B34+1 -> 18 | F35: =IF($D35="",0,IF($E35="",0,INDEX($J$19:$P$24,MATCH($D35,$I$19:$I$24,1),MATCH($E35,$J$17:$P$17,0)))) -> 0 | G35: =IF($D35="",0,IF($E35="",0,INDEX($R$19:$X$24,MATCH($D35,$I$19:$I$24,1),MATCH($E35,$R$17:$X$17,0)))) -> 0
B36: =B35+1 -> 19 | F36: =IF($D36="",0,IF($E36="",0,INDEX($J$19:$P$24,MATCH($D36,$I$19:$I$24,1),MATCH($E36,$J$17:$P$17,0)))) -> 0 | G36: =IF($D36="",0,IF($E36="",0,INDEX($R$19:$X$24,MATCH($D36,$I$19:$I$24,1),MATCH($E36,$R$17:$X$17,0)))) -> 0
... B42: =B41+1 -> 25 | F42: =IF($D42="",0,IF($E42="",0,INDEX($J$19:$P$24,MATCH($D42,$I$19:$I$24,1),MATCH($E42,$J$17:$P$17,0)))) -> 0 | G42: =IF($D42="",0,IF($E42="",0,INDEX($R$19:$X$24,MATCH($D42,$I$19:$I$24,1),MATCH($E42,$R$17:$X$17,0)))) -> 0
B43: Totals | D43: =SUM(D18:D42) -> 0 | F43: =SUM(F18:F42) -> 0 | G43: =SUM(G18:G42) -> 0
E54: vvvvvvvvvv Notes: Selecting "xx" means the owner is providing the equipment | I54: Notes: "x" implies that we need to include an estimate for this item. If the equipment provider has included the item in their package proporsal select "xx". Also use "xx" if the owner is providing but we have to install
B55: New Packaged Units | F55: Cost Calculator (Option) | H55: Supplier Quote (Option) | R55: DUCT | S55: DUCT | T55: Equipment Materials ------------------------------------------------------------------------------------------------------------------------------------------------------------------------------------------------------------------------------------------------------------------------------------------------------------------------------------------------------------------------------------------------------------------ | AE55: Misc: | AF55: 0.025 | AH55: Duct Materials-------------------------------------------- | AK55: Equipment Labor-------------------------------------------------------------------------------------------------------------------------------------------------------------------------------------------------------------------------------------------------------------------------------------------------------------------------------------------------------------------------------------------------------------------- | AX55: Duct Labor----------------------------------------------------------------------------- | BC55: Materials Cost | BR55: Equipment Labor Cost | CQ55: Duct Labor
B56: Unit | C56: Name | D56: Cool (Tons) | E56: Owner Provided ("xx") | F56: Base Cost ($/ton) | G56: Est. Equipment Cost ($) | H56: Equipment Cost ($) | I56: Standard Curb ("x/xx") | J56: Metal Roof Curb ("x/xx") | K56: Curb Adapter ("x/xx") | L56: Economizer ("x/xx") | M56: PVC Condensate ("x/xx") | N56: CU Condensate ("x/xx") | O56: Thermostat ("x/xx") | P56: Smoke Detectors ("x/xx") | Q56: Sensors (CO/Temp) (Qty) | R56: New Drops ("x/xx") | S56: Drum Louvers ("x/xx") | T56: Economizer ($) | U56: Standard Curb ($) | V56: Metal Roof Curb ($) | W56: Curb Adapter ($) | X56: PVC Cond. ($) | Y56: CU Cond. ($) | Z56: Thermostat ($) | AA56: Smoke Detectors ($) | AB56: Sensors (CO/Temp) ($) | AC56: Stat Wire (CO/Temp) ($) | AD56: Base + Quoted Price ($) | AE56: Accessories ($) | AF56: Misc/Consumables | AG56: Total Materials | AH56: New Drops ($) | AI56: Drum Louvers ($) | AJ56: Total Materials ($) | AK56: Base Equipment ($) | AL56: Standard Curb ($) | AM56: Metal Roof Curb ($) | AN56: Curb Adapter ($) | AO56: Economizer ($) | AP56: PVC Cond. ($) | AQ56: CU Cond. ($) | AR56: Thermostat ($) | AS56: Smoke Detectors ($) | AT56: Sensors (CO/Temp) ($) | AU56: Stat Wire (CO/Temp) ($) | AV56: Startup & Testing | AW56: Labor Total ($) | AX56: New Drops ($) | AY56: Drum Louvers ($) | AZ56: Labor Total ($) | BA56: Notes | BD56: Economizer | BF56: Standard Curb | BH56: Metal Roof Curb | BJ56: Curb Adapter | BN56: New Drops | BP56: Drum Louvers (Supply + Return) | BS56: Base Unit | BU56: Standard Curb | BW56: Metal Curb | BY56: Curb Adapter | CA56: Economizer | CC56: PVC Cond | CE56: CU Cond | CG56: Thermostat | CI56: Smoke Detectors | CK56: Sensors | CM56: Stat Wire | CO56: Start Up | CQ56: New Drops | CS56: Drum Louvers (+ Returns)
...

Sheet CW Pipe Sched
B1: =IF(Summary!$C$1="","",Summary!$C$1)
B2: PIPING WRAP INSTALLATION | G2: Scale - Ft/Unit | I2: 1 | K2: Incidentals | L2: 0.1 | N2: 0.1
B3: Item | C3: Sysrem Type | D3: Source | E3: Type | F3: SHT MEAS LEN (ft) | G3: Dia (in) | H3: Pipe ("x") | I3: Ins ("x") | J3: Calc. Length (Ft) | K3: CS Mat ($) | L3: CS Misc ($) | M3: Ins Mat ($) | N3: Ins Misc ($) | O3: Total Mat ($) | P3: CS labor ($) | Q3: Ins Labor ($) | R3: Total Labor | S3: Mat+Lab | V3: Material | W3: Type | X3: Dia (in) | Y3: Mat. ($/Ft) | Z3: Install ($/Ft)
B4: 1 | C4: CW | D4: CHILLER | E4: CS | F4: 0 | G4: 6 | H4: x | I4: x | J4: =IF(F4="","",+$I$2*F4) -> 0 | K4: =IF(OR($E4<>"CS",$H4<>"x"),0,INDEX($Y$4:$Y$14,MATCH($G4,$X$4:$X14,0),1))*J4*1.1 -> 0 | L4: =K4*$L$2 -> 0 | M4: =IF($I4<>"x",0,INDEX($Y$27:$Y$37,MATCH($G4,$X$27:$X37,0),1))*J4*1.1 -> 0 | N4: =M4*$N$2 -> 0 | O4: =SUM(K4:N4) -> 0 | P4: =IF(OR($E4<>"CS",$H4<>"x"),0,INDEX($Z$4:$Z$14,MATCH($G4,$X$4:$X14,0),1))*J4*1.1 -> 0 | Q4: =IF($I4<>"x",0,INDEX($Z$27:$Z$37,MATCH($G4,$X$27:$X37,0),1))*J4*1.1 -> 0 | R4: =SUM(P4:Q4) -> 0 | S4: =R4+O4 -> 0 | V4: CS | W4: Sched 40 | X4: 0.75 | Y4: 2.1 | Z4: 10
B5: =1+B4 -> 2 | C5: CW | D5: CHILLER | E5: CS | F5: 0 | G5: 6 | H5: x | J5: =IF(F5="","",+$I$2*F5) -> 0 | K5: =IF(OR($E5<>"CS",$H5<>"x"),0,INDEX($Y$4:$Y$14,MATCH($G5,$X$4:$X15,0),1))*J5*1.1 -> 0 | L5: =K5*$L$2 -> 0 | M5: =IF($I5<>"x",0,INDEX($Y$27:$Y$37,MATCH($G5,$X$27:$X38,0),1))*J5*1.1 -> 0 | N5: =M5*$N$2 -> 0 | O5: =SUM(K5:N5) -> 0 | P5: =IF(OR($E5<>"CS",$H5<>"x"),0,INDEX($Z$4:$Z$14,MATCH($G5,$X$4:$X15,0),1))*J5*1.1 -> 0 | Q5: =IF($I5<>"x",0,INDEX($Z$27:$Z$37,MATCH($G5,$X$27:$X38,0),1))*J5*1.1 -> 0 | R5: =SUM(P5:Q5) -> 0 | S5: =R5+O5 -> 0 | V5: CS | W5: Sched 40 | X5: 1 | Y5: 3.14 | Z5: 10
B6: =1+B5 -> 3 | C6: CW | D6: CHILLER | E6: CS | F6: 0 | G6: 2 | H6: x | J6: =IF(F6="","",+$I$2*F6) -> 0 | K6: =IF(OR($E6<>"CS",$H6<>"x"),0,INDEX($Y$4:$Y$14,MATCH($G6,$X$4:$X16,0),1))*J6*1.1 -> 0 | L6: =K6*$L$2 -> 0 | M6: =IF($I6<>"x",0,INDEX($Y$27:$Y$37,MATCH($G6,$X$27:$X39,0),1))*J6*1.1 -> 0 | N6: =M6*$N$2 -> 0 | O6: =SUM(K6:N6) -> 0 | P6: =IF(OR($E6<>"CS",$H6<>"x"),0,INDEX($Z$4:$Z$14,MATCH($G6,$X$4:$X16,0),1))*J6*1.1 -> 0 | Q6: =IF($I6<>"x",0,INDEX($Z$27:$Z$37,MATCH($G6,$X$27:$X39,0),1))*J6*1.1 -> 0 | R6: =SUM(P6:Q6) -> 0 | S6: =R6+O6 -> 0 | V6: CS | W6: Sched 40 | X6: 1.25 | Y6: 4 | Z6: 10
B7: =1+B6 -> 4 | C7: CW | D7: CHILLER | E7: CS | F7: 0 | G7: 2 | H7: x | J7: =IF(F7="","",+$I$2*F7) -> 0 | K7: =IF(OR($E7<>"CS",$H7<>"x"),0,INDEX($Y$4:$Y$14,MATCH($G7,$X$4:$X17,0),1))*J7*1.1 -> 0 | L7: =K7*$L$2 -> 0 | M7: =IF($I7<>"x",0,INDEX($Y$27:$Y$37,MATCH($G7,$X$27:$X40,0),1))*J7*1.1 -> 0 | N7: =M7*$N$2 -> 0 | O7: =SUM(K7:N7) -> 0 | P7: =IF(OR($E7<>"CS",$H7<>"x"),0,INDEX($Z$4:$Z$14,MATCH($G7,$X$4:$X17,0),1))*J7*1.1 -> 0 | Q7: =IF($I7<>"x",0,INDEX($Z$27:$Z$37,MATCH($G7,$X$27:$X40,0),1))*J7*1.1 -> 0 | R7: =SUM(P7:Q7) -> 0 | S7: =R7+O7 -> 0 | V7: CS | W7: Sched 40 | X7: 2 | Y7: 6.9 | Z7: 10
B8: =1+B7 -> 5 | C8: CW | D8: CHILLER | E8: CS | F8: 0 | G8: 2 | H8: x | J8: =IF(F8="","",+$I$2*F8) -> 0 | K8: =IF(OR($E8<>"CS",$H8<>"x"),0,INDEX($Y$4:$Y$14,MATCH($G8,$X$4:$X18,0),1))*J8*1.1 -> 0 | L8: =K8*$L$2 -> 0 | M8: =IF($I8<>"x",0,INDEX($Y$27:$Y$37,MATCH($G8,$X$27:$X41,0),1))*J8*1.1 -> 0 | N8: =M8*$N$2 -> 0 | O8: =SUM(K8:N8) -> 0 | P8: =IF(OR($E8<>"CS",$H8<>"x"),0,INDEX($Z$4:$Z$14,MATCH($G8,$X$4:$X18,0),1))*J8*1.1 -> 0 | Q8: =IF($I8<>"x",0,INDEX($Z$27:$Z$37,MATCH($G8,$X$27:$X41,0),1))*J8*1.1 -> 0 | R8: =SUM(P8:Q8) -> 0 | S8: =R8+O8 -> 0 | V8: CS | W8: Sched 40 | X8: 3 | Y8: 12.8 | Z8: 10
B9: =1+B8 -> 6 | C9: CW | D9: CHILLER | E9: CS | F9: 0 | G9: 3 | H9: x | J9: =IF(F9="","",+$I$2*F9) -> 0 | K9: =IF(OR($E9<>"CS",$H9<>"x"),0,INDEX($Y$4:$Y$14,MATCH($G9,$X$4:$X19,0),1))*J9*1.1 -> 0 | L9: =K9*$L$2 -> 0 | M9: =IF($I9<>"x",0,INDEX($Y$27:$Y$37,MATCH($G9,$X$27:$X42,0),1))*J9*1.1 -> 0 | N9: =M9*$N$2 -> 0 | O9: =SUM(K9:N9) -> 0 | P9: =IF(OR($E9<>"CS",$H9<>"x"),0,INDEX($Z$4:$Z$14,MATCH($G9,$X$4:$X19,0),1))*J9*1.1 -> 0 | Q9: =IF($I9<>"x",0,INDEX($Z$27:$Z$37,MATCH($G9,$X$27:$X42,0),1))*J9*1.1 -> 0 | R9: =SUM(P9:Q9) -> 0 | S9: =R9+O9 -> 0 | V9: CS | W9: Sched 40 | X9: 4 | Y9: 20 | Z9: 13
B10: =1+B9 -> 7 | C10: CW | D10: CHILLER | E10: CS | F10: 0 | G10: 3 | H10: x | J10: =IF(F10="","",+$I$2*F10) -> 0 | K10: =IF(OR($E10<>"CS",$H10<>"x"),0,INDEX($Y$4:$Y$14,MATCH($G10,$X$4:$X20,0),1))*J10*1.1 -> 0 | L10: =K10*$L$2 -> 0 | M10: =IF($I10<>"x",0,INDEX($Y$27:$Y$37,MATCH($G10,$X$27:$X43,0),1))*J10*1.1 -> 0 | N10: =M10*$N$2 -> 0 | O10: =SUM(K10:N10) -> 0 | P10: =IF(OR($E10<>"CS",$H10<>"x"),0,INDEX($Z$4:$Z$14,MATCH($G10,$X$4:$X20,0),1))*J10*1.1 -> 0 | Q10: =IF($I10<>"x",0,INDEX($Z$27:$Z$37,MATCH($G10,$X$27:$X43,0),1))*J10*1.1 -> 0 | R10: =SUM(P10:Q10) -> 0 | S10: =R10+O10 -> 0 | V10: CS | W10: Sched 40 | X10: 5 | Y10: 28 | Z10: 13
B11: =1+B10 -> 8 | C11: CW | D11: CHILLER | E11: CS | F11: 0 | G11: 2 | H11: x | J11: =IF(F11="","",+$I$2*F11) -> 0 | K11: =IF(OR($E11<>"CS",$H11<>"x"),0,INDEX($Y$4:$Y$14,MATCH($G11,$X$4:$X21,0),1))*J11*1.1 -> 0 | L11: =K11*$L$2 -> 0 | M11: =IF($I11<>"x",0,INDEX($Y$27:$Y$37,MATCH($G11,$X$27:$X44,0),1))*J11*1.1 -> 0 | N11: =M11*$N$2 -> 0 | O11: =SUM(K11:N11) -> 0 | P11: =IF(OR($E11<>"CS",$H11<>"x"),0,INDEX($Z$4:$Z$14,MATCH($G11,$X$4:$X21,0),1))*J11*1.1 -> 0 | Q11: =IF($I11<>"x",0,INDEX($Z$27:$Z$37,MATCH($G11,$X$27:$X44,0),1))*J11*1.1 -> 0 | R11: =SUM(P11:Q11) -> 0 | S11: =R11+O11 -> 0 | V11: CS | W11: Sched 40 | X11: 6 | Y11: 30 | Z11: 13
B12: =1+B11 -> 9 | C12: CW | D12: CHILLER | E12: CS | F12: 0 | G12: 2 | H12: x | J12: =IF(F12="","",+$I$2*F12) -> 0 | K12: =IF(OR($E12<>"CS",$H12<>"x"),0,INDEX($Y$4:$Y$14,MATCH($G12,$X$4:$X22,0),1))*J12*1.1 -> 0 | L12: =K12*$L$2 -> 0 | M12: =IF($I12<>"x",0,INDEX($Y$27:$Y$37,MATCH($G12,$X$27:$X45,0),1))*J12*1.1 -> 0 | N12: =M12*$N$2 -> 0 | O12: =SUM(K12:N12) -> 0 | P12: =IF(OR($E12<>"CS",$H12<>"x"),0,INDEX($Z$4:$Z$14,MATCH($G12,$X$4:$X22,0),1))*J12*1.1 -> 0 | Q12: =IF($I12<>"x",0,INDEX($Z$27:$Z$37,MATCH($G12,$X$27:$X45,0),1))*J12*1.1 -> 0 | R12: =SUM(P12:Q12) -> 0 | S12: =R12+O12 -> 0 | V12: CS | W12: Sched 40 | X12: 8 | Y12: 49 | Z12: 13
B13: =1+B12 -> 10 | C13: CW | D13: CHILLER | E13: CS | F13: 0 | G13: 1.25 | H13: x | J13: =IF(F13="","",+$I$2*F13) -> 0 | K13: =IF(OR($E13<>"CS",$H13<>"x"),0,INDEX($Y$4:$Y$14,MATCH($G13,$X$4:$X23,0),1))*J13*1.1 -> 0 | L13: =K13*$L$2 -> 0 | M13: =IF($I13<>"x",0,INDEX($Y$27:$Y$37,MATCH($G13,$X$27:$X46,0),1))*J13*1.1 -> 0 | N13: =M13*$N$2 -> 0 | O13: =SUM(K13:N13) -> 0 | P13: =IF(OR($E13<>"CS",$H13<>"x"),0,INDEX($Z$4:$Z$14,MATCH($G13,$X$4:$X23,0),1))*J13*1.1 -> 0 | Q13: =IF($I13<>"x",0,INDEX($Z$27:$Z$37,MATCH($G13,$X$27:$X46,0),1))*J13*1.1 -> 0 | R13: =SUM(P13:Q13) -> 0 | S13: =R13+O13 -> 0 | V13: CS | W13: Sched 40 | X13: 10 | Y13: 69 | Z13: 18
B14: =1+B13 -> 11 | C14: CW | D14: CHILLER | E14: CS | F14: 0 | G14: 1.25 | H14: x | J14: =IF(F14="","",+$I$2*F14) -> 0 | K14: =IF(OR($E14<>"CS",$H14<>"x"),0,INDEX($Y$4:$Y$14,MATCH($G14,$X$4:$X24,0),1))*J14*1.1 -> 0 | L14: =K14*$L$2 -> 0 | M14: =IF($I14<>"x",0,INDEX($Y$27:$Y$37,MATCH($G14,$X$27:$X47,0),1))*J14*1.1 -> 0 | N14: =M14*$N$2 -> 0 | O14: =SUM(K14:N14) -> 0 | P14: =IF(OR($E14<>"CS",$H14<>"x"),0,INDEX($Z$4:$Z$14,MATCH($G14,$X$4:$X24,0),1))*J14*1.1 -> 0 | Q14: =IF($I14<>"x",0,INDEX($Z$27:$Z$37,MATCH($G14,$X$27:$X47,0),1))*J14*1.1 -> 0 | R14: =SUM(P14:Q14) -> 0 | S14: =R14+O14 -> 0 | V14: CS | W14: Sched 40 | X14: 12 | Y14: 84 | Z14: 18
B15: =1+B14 -> 12 | C15: CW | D15: CHILLER | E15: CS | F15: 0 | G15: 1 | H15: x | J15: =IF(F15="","",+$I$2*F15) -> 0 | K15: =IF(OR($E15<>"CS",$H15<>"x"),0,INDEX($Y$4:$Y$14,MATCH($G15,$X$4:$X25,0),1))*J15*1.1 -> 0 | L15: =K15*$L$2 -> 0 | M15: =IF($I15<>"x",0,INDEX($Y$27:$Y$37,MATCH($G15,$X$27:$X48,0),1))*J15*1.1 -> 0 | N15: =M15*$N$2 -> 0 | O15: =SUM(K15:N15) -> 0 | P15: =IF(OR($E15<>"CS",$H15<>"x"),0,INDEX($Z$4:$Z$14,MATCH($G15,$X$4:$X25,0),1))*J15*1.1 -> 0 | Q15: =IF($I15<>"x",0,INDEX($Z$27:$Z$37,MATCH($G15,$X$27:$X48,0),1))*J15*1.1 -> 0 | R15: =SUM(P15:Q15) -> 0 | S15: =R15+O15 -> 0 | V15: SS | W15: Sched 40 | X15: 1 | Z15: =Z4*1.5 -> 15
B16: =1+B15 -> 13 | C16: CW | D16: CHILLER | E16: CS | F16: 0 | G16: 1 | H16: x | J16: =IF(F16="","",+$I$2*F16) -> 0 | K16: =IF(OR($E16<>"CS",$H16<>"x"),0,INDEX($Y$4:$Y$14,MATCH($G16,$X$4:$X26,0),1))*J16*1.1 -> 0 | L16: =K16*$L$2 -> 0 | M16: =IF($I16<>"x",0,INDEX($Y$27:$Y$37,MATCH($G16,$X$27:$X49,0),1))*J16*1.1 -> 0 | N16: =M16*$N$2 -> 0 | O16: =SUM(K16:N16) -> 0 | P16: =IF(OR($E16<>"CS",$H16<>"x"),0,INDEX($Z$4:$Z$14,MATCH($G16,$X$4:$X26,0),1))*J16*1.1 -> 0 | Q16: =IF($I16<>"x",0,INDEX($Z$27:$Z$37,MATCH($G16,$X$27:$X49,0),1))*J16*1.1 -> 0 | R16: =SUM(P16:Q16) -> 0 | S16: =R16+O16 -> 0 | V16: SS | W16: Sched 40 | X16: 2 | Z16: =Z5*1.5 -> 15
B17: =1+B16 -> 14 | C17: CW | D17: CHILLER | E17: CS | F17: 0 | G17: 0.75 | H17: x | J17: =IF(F17="","",+$I$2*F17) -> 0 | K17: =IF(OR($E17<>"CS",$H17<>"x"),0,INDEX($Y$4:$Y$14,MATCH($G17,$X$4:$X27,0),1))*J17*1.1 -> 0 | L17: =K17*$L$2 -> 0 | M17: =IF($I17<>"x",0,INDEX($Y$27:$Y$37,MATCH($G17,$X$27:$X50,0),1))*J17*1.1 -> 0 | N17: =M17*$N$2 -> 0 | O17: =SUM(K17:N17) -> 0 | P17: =IF(OR($E17<>"CS",$H17<>"x"),0,INDEX($Z$4:$Z$14,MATCH($G17,$X$4:$X27,0),1))*J17*1.1 -> 0 | Q17: =IF($I17<>"x",0,INDEX($Z$27:$Z$37,MATCH($G17,$X$27:$X50,0),1))*J17*1.1 -> 0 | R17: =SUM(P17:Q17) -> 0 | S17: =R17+O17 -> 0 | V17: SS | W17: Sched 40 | X17: 3 | Z17: =Z6*1.5 -> 15
B18: =1+B17 -> 15 | C18: CW | D18: CHILLER | E18: CS | F18: 0 | G18: 0.75 | H18: x | J18: =IF(F18="","",+$I$2*F18) -> 0 | K18: =IF(OR($E18<>"CS",$H18<>"x"),0,INDEX($Y$4:$Y$14,MATCH($G18,$X$4:$X28,0),1))*J18*1.1 -> 0 | L18: =K18*$L$2 -> 0 | M18: =IF($I18<>"x",0,INDEX($Y$27:$Y$37,MATCH($G18,$X$27:$X51,0),1))*J18*1.1 -> 0 | N18: =M18*$N$2 -> 0 | O18: =SUM(K18:N18) -> 0 | P18: =IF(OR($E18<>"CS",$H18<>"x"),0,INDEX($Z$4:$Z$14,MATCH($G18,$X$4:$X28,0),1))*J18*1.1 -> 0 | Q18: =IF($I18<>"x",0,INDEX($Z$27:$Z$37,MATCH($G18,$X$27:$X51,0),1))*J18*1.1 -> 0 | R18: =SUM(P18:Q18) -> 0 | S18: =R18+O18 -> 0 | V18: SS | W18: Sched 40 | X18: 4 | Z18: =Z7*1.5 -> 15
B19: =1+B18 -> 16 | C19: CW | D19: CHILLER | E19: CS | F19: 0 | G19: 0.75 | H19: x | I19: x | J19: =IF(F19="","",+$I$2*F19) -> 0 | K19: =IF(OR($E19<>"CS",$H19<>"x"),0,INDEX($Y$4:$Y$14,MATCH($G19,$X$4:$X29,0),1))*J19*1.1 -> 0 | L19: =K19*$L$2 -> 0 | M19: =IF($I19<>"x",0,INDEX($Y$27:$Y$37,MATCH($G19,$X$27:$X52,0),1))*J19*1.1 -> 0 | N19: =M19*$N$2 -> 0 | O19: =SUM(K19:N19) -> 0 | P19: =IF(OR($E19<>"CS",$H19<>"x"),0,INDEX($Z$4:$Z$14,MATCH($G19,$X$4:$X29,0),1))*J19*1.1 -> 0 | Q19: =IF($I19<>"x",0,INDEX($Z$27:$Z$37,MATCH($G19,$X$27:$X52,0),1))*J19*1.1 -> 0 | R19: =SUM(P19:Q19) -> 0 | S19: =R19+O19 -> 0 | V19: SS | W19: Sched 40 | X19: 5 | Z19: =Z8*1.5 -> 15
B20: =1+B19 -> 17 | C20: CW | D20: CHILLER | E20: CS | F20: 0 | G20: 0.75 | H20: x | I20: x | J20: =IF(F20="","",+$I$2*F20) -> 0 | K20: =IF(OR($E20<>"CS",$H20<>"x"),0,INDEX($Y$4:$Y$14,MATCH($G20,$X$4:$X30,0),1))*J20*1.1 -> 0 | L20: =K20*$L$2 -> 0 | M20: =IF($I20<>"x",0,INDEX($Y$27:$Y$37,MATCH($G20,$X$27:$X53,0),1))*J20*1.1 -> 0 | N20: =M20*$N$2 -> 0 | O20: =SUM(K20:N20) -> 0 | P20: =IF(OR($E20<>"CS",$H20<>"x"),0,INDEX($Z$4:$Z$14,MATCH($G20,$X$4:$X30,0),1))*J20*1.1 -> 0 | Q20: =IF($I20<>"x",0,INDEX($Z$27:$Z$37,MATCH($G20,$X$27:$X53,0),1))*J20*1.1 -> 0 | R20: =SUM(P20:Q20) -> 0 | S20: =R20+O20 -> 0 | V20: SS | W20: Sched 40 | X20: 6 | Z20: =Z9*1.5 -> 19.5
B21: =1+B20 -> 18 | C21: CW | D21: CHILLER | E21: CS | F21: 0 | G21: 0.75 | H21: x | I21: x | J21: =IF(F21="","",+$I$2*F21) -> 0 | K21: =IF(OR($E21<>"CS",$H21<>"x"),0,INDEX($Y$4:$Y$14,MATCH($G21,$X$4:$X31,0),1))*J21*1.1 -> 0 | L21: =K21*$L$2 -> 0 | M21: =IF($I21<>"x",0,INDEX($Y$27:$Y$37,MATCH($G21,$X$27:$X54,0),1))*J21*1.1 -> 0 | N21: =M21*$N$2 -> 0 | O21: =SUM(K21:N21) -> 0 | P21: =IF(OR($E21<>"CS",$H21<>"x"),0,INDEX($Z$4:$Z$14,MATCH($G21,$X$4:$X31,0),1))*J21*1.1 -> 0 | Q21: =IF($I21<>"x",0,INDEX($Z$27:$Z$37,MATCH($G21,$X$27:$X54,0),1))*J21*1.1 -> 0 | R21: =SUM(P21:Q21) -> 0 | S21: =R21+O21 -> 0 | V21: SS | W21: Sched 40 | X21: 7 | Z21: =Z10*1.5 -> 19.5
B22: =1+B21 -> 19 | C22: CW | D22: CHILLER | E22: CS | F22: 0 | G22: 0.75 | H22: x | I22: x | J22: =IF(F22="","",+$I$2*F22) -> 0 | K22: =IF(OR($E22<>"CS",$H22<>"x"),0,INDEX($Y$4:$Y$14,MATCH($G22,$X$4:$X32,0),1))*J22*1.1 -> 0 | L22: =K22*$L$2 -> 0 | M22: =IF($I22<>"x",0,INDEX($Y$27:$Y$37,MATCH($G22,$X$27:$X55,0),1))*J22*1.1 -> 0 | N22: =M22*$N$2 -> 0 | O22: =SUM(K22:N22) -> 0 | P22: =IF(OR($E22<>"CS",$H22<>"x"),0,INDEX($Z$4:$Z$14,MATCH($G22,$X$4:$X32,0),1))*J22*1.1 -> 0 | Q22: =IF($I22<>"x",0,INDEX($Z$27:$Z$37,MATCH($G22,$X$27:$X55,0),1))*J22*1.1 -> 0 | R22: =SUM(P22:Q22) -> 0 | S22: =R22+O22 -> 0 | V22: SS | W22: Sched 40 | X22: 8 | Z22: =Z11*1.5 -> 19.5
B23: =1+B22 -> 20 | C23: CW | D23: CHILLER | E23: CS | F23: 0 | G23: 0.75 | H23: x | I23: x | J23: =IF(F23="","",+$I$2*F23) -> 0 | K23: =IF(OR($E23<>"CS",$H23<>"x"),0,INDEX($Y$4:$Y$14,MATCH($G23,$X$4:$X33,0),1))*J23*1.1 -> 0 | L23: =K23*$L$2 -> 0 | M23: =IF($I23<>"x",0,INDEX($Y$27:$Y$37,MATCH($G23,$X$27:$X56,0),1))*J23*1.1 -> 0 | N23: =M23*$N$2 -> 0 | O23: =SUM(K23:N23) -> 0 | P23: =IF(OR($E23<>"CS",$H23<>"x"),0,INDEX($Z$4:$Z$14,MATCH($G23,$X$4:$X33,0),1))*J23*1.1 -> 0 | Q23: =IF($I23<>"x",0,INDEX($Z$27:$Z$37,MATCH($G23,$X$27:$X56,0),1))*J23*1.1 -> 0 | R23: =SUM(P23:Q23) -> 0 | S23: =R23+O23 -> 0 | V23: SS | W23: Sched 40 | X23: 9 | Z23: =Z12*1.5 -> 19.5
B24: =1+B23 -> 21 | C24: CW | D24: CHILLER | E24: CS | F24: 0 | G24: 0.75 | H24: x | I24: x | J24: =IF(F24="","",+$I$2*F24) -> 0 | K24: =IF(OR($E24<>"CS",$H24<>"x"),0,INDEX($Y$4:$Y$14,MATCH($G24,$X$4:$X34,0),1))*J24*1.1 -> 0 | L24: =K24*$L$2 -> 0 | M24: =IF($I24<>"x",0,INDEX($Y$27:$Y$37,MATCH($G24,$X$27:$X57,0),1))*J24*1.1 -> 0 | N24: =M24*$N$2 -> 0 | O24: =SUM(K24:N24) -> 0 | P24: =IF(OR($E24<>"CS",$H24<>"x"),0,INDEX($Z$4:$Z$14,MATCH($G24,$X$4:$X34,0),1))*J24*1.1 -> 0 | Q24: =IF($I24<>"x",0,INDEX($Z$27:$Z$37,MATCH($G24,$X$27:$X57,0),1))*J24*1.1 -> 0 | R24: =SUM(P24:Q24) -> 0 | S24: =R24+O24 -> 0 | V24: SS | W24: Sched 40 | X24: 10 | Z24: =Z13*1.5 -> 27
B25: =1+B24 -> 22 | C25: CW | D25: CHILLER | E25: CS | F25: 0 | G25: 0.75 | H25: x | I25: x | J25: =IF(F25="","",+$I$2*F25) -> 0 | K25: =IF(OR($E25<>"CS",$H25<>"x"),0,INDEX($Y$4:$Y$14,MATCH($G25,$X$4:$X35,0),1))*J25*1.1 -> 0 | L25: =K25*$L$2 -> 0 | M25: =IF($I25<>"x",0,INDEX($Y$27:$Y$37,MATCH($G25,$X$27:$X58,0),1))*J25*1.1 -> 0 | N25: =M25*$N$2 -> 0 | O25: =SUM(K25:N25) -> 0 | P25: =IF(OR($E25<>"CS",$H25<>"x"),0,INDEX($Z$4:$Z$14,MATCH($G25,$X$4:$X35,0),1))*J25*1.1 -> 0 | Q25: =IF($I25<>"x",0,INDEX($Z$27:$Z$37,MATCH($G25,$X$27:$X58,0),1))*J25*1.1 -> 0 | R25: =SUM(P25:Q25) -> 0 | S25: =R25+O25 -> 0 | V25: SS | W25: Sched 40 | X25: 11 | Z25: =Z14*1.5 -> 27
B26: =1+B25 -> 23 | C26: CW | D26: CHILLER | E26: CS | F26: 0 | G26: 0.75 | H26: x | I26: x | J26: =IF(F26="","",+$I$2*F26) -> 0 | K26: =IF(OR($E26<>"CS",$H26<>"x"),0,INDEX($Y$4:$Y$14,MATCH($G26,$X$4:$X36,0),1))*J26*1.1 -> 0 | L26: =K26*$L$2 -> 0 | M26: =IF($I26<>"x",0,INDEX($Y$27:$Y$37,MATCH($G26,$X$27:$X59,0),1))*J26*1.1 -> 0 | N26: =M26*$N$2 -> 0 | O26: =SUM(K26:N26) -> 0 | P26: =IF(OR($E26<>"CS",$H26<>"x"),0,INDEX($Z$4:$Z$14,MATCH($G26,$X$4:$X36,0),1))*J26*1.1 -> 0 | Q26: =IF($I26<>"x",0,INDEX($Z$27:$Z$37,MATCH($G26,$X$27:$X59,0),1))*J26*1.1 -> 0 | R26: =SUM(P26:Q26) -> 0 | S26: =R26+O26 -> 0 | V26: SS | W26: Sched 40 | X26: 12 | Z26: =Z15*1.5 -> 22.5
B27: =1+B26 -> 24 | C27: CW | D27: CHILLER | E27: CS | F27: 0 | G27: 0.75 | H27: x | I27: x | J27: =IF(F27="","",+$I$2*F27) -> 0 | K27: =IF(OR($E27<>"CS",$H27<>"x"),0,INDEX($Y$4:$Y$14,MATCH($G27,$X$4:$X37,0),1))*J27*1.1 -> 0 | L27: =K27*$L$2 -> 0 | M27: =IF($I27<>"x",0,INDEX($Y$27:$Y$37,MATCH($G27,$X$27:$X60,0),1))*J27*1.1 -> 0 | N27: =M27*$N$2 -> 0 | O27: =SUM(K27:N27) -> 0 | P27: =IF(OR($E27<>"CS",$H27<>"x"),0,INDEX($Z$4:$Z$14,MATCH($G27,$X$4:$X37,0),1))*J27*1.1 -> 0 | Q27: =IF($I27<>"x",0,INDEX($Z$27:$Z$37,MATCH($G27,$X$27:$X60,0),1))*J27*1.1 -> 0 | R27: =SUM(P27:Q27) -> 0 | S27: =R27+O27 -> 0 | V27: Insulation | W27: 2" thick | X27: 0.75 | Y27: 4.5 | Z27: 5
B28: =1+B27 -> 25 | C28: CW | D28: CHILLER | E28: CS | F28: 0 | G28: 0.75 | H28: x | I28: x | J28: =IF(F28="","",+$I$2*F28) -> 0 | K28: =IF(OR($E28<>"CS",$H28<>"x"),0,INDEX($Y$4:$Y$14,MATCH($G28,$X$4:$X38,0),1))*J28*1.1 -> 0 | L28: =K28*$L$2 -> 0 | M28: =IF($I28<>"x",0,INDEX($Y$27:$Y$37,MATCH($G28,$X$27:$X61,0),1))*J28*1.1 -> 0 | N28: =M28*$N$2 -> 0 | O28: =SUM(K28:N28) -> 0 | P28: =IF(OR($E28<>"CS",$H28<>"x"),0,INDEX($Z$4:$Z$14,MATCH($G28,$X$4:$X38,0),1))*J28*1.1 -> 0 | Q28: =IF($I28<>"x",0,INDEX($Z$27:$Z$37,MATCH($G28,$X$27:$X61,0),1))*J28*1.1 -> 0 | R28: =SUM(P28:Q28) -> 0 | S28: =R28+O28 -> 0 | V28: Insulation | W28: 2" thick | X28: 1 | Y28: 5 | Z28: 5
B29: =1+B28 -> 26 | C29: CW | D29: CHILLER | E29: CS | F29: 0 | G29: 0.75 | H29: x | I29: x | J29: =IF(F29="","",+$I$2*F29) -> 0 | K29: =IF(OR($E29<>"CS",$H29<>"x"),0,INDEX($Y$4:$Y$14,MATCH($G29,$X$4:$X39,0),1))*J29*1.1 -> 0 | L29: =K29*$L$2 -> 0 | M29: =IF($I29<>"x",0,INDEX($Y$27:$Y$37,MATCH($G29,$X$27:$X62,0),1))*J29*1.1 -> 0 | N29: =M29*$N$2 -> 0 | O29: =SUM(K29:N29) -> 0 | P29: =IF(OR($E29<>"CS",$H29<>"x"),0,INDEX($Z$4:$Z$14,MATCH($G29,$X$4:$X39,0),1))*J29*1.1 -> 0 | Q29: =IF($I29<>"x",0,INDEX($Z$27:$Z$37,MATCH($G29,$X$27:$X62,0),1))*J29*1.1 -> 0 | R29: =SUM(P29:Q29) -> 0 | S29: =R29+O29 -> 0 | V29: Insulation | W29: 2" thick | X29: 1.25 | Y29: 6 | Z29: 5
B30: =1+B29 -> 27 | C30: CW | D30: CHILLER | E30: CS | F30: 0 | G30: 0.75 | H30: x | I30: x | J30: =IF(F30="","",+$I$2*F30) -> 0 | K30: =IF(OR($E30<>"CS",$H30<>"x"),0,INDEX($Y$4:$Y$14,MATCH($G30,$X$4:$X40,0),1))*J30*1.1 -> 0 | L30: =K30*$L$2 -> 0 | M30: =IF($I30<>"x",0,INDEX($Y$27:$Y$37,MATCH($G30,$X$27:$X63,0),1))*J30*1.1 -> 0 | N30: =M30*$N$2 -> 0 | O30: =SUM(K30:N30) -> 0 | P30: =IF(OR($E30<>"CS",$H30<>"x"),0,INDEX($Z$4:$Z$14,MATCH($G30,$X$4:$X40,0),1))*J30*1.1 -> 0 | Q30: =IF($I30<>"x",0,INDEX($Z$27:$Z$37,MATCH($G30,$X$27:$X63,0),1))*J30*1.1 -> 0 | R30: =SUM(P30:Q30) -> 0 | S30: =R30+O30 -> 0 | V30: Insulation | W30: 2" thick | X30: 2 | Y30: 10 | Z30: 5
B31: =1+B30 -> 28 | C31: CW | D31: CHILLER | E31: CS | F31: 0 | G31: 0.75 | H31: x | I31: x | J31: =IF(F31="","",+$I$2*F31) -> 0 | K31: =IF(OR($E31<>"CS",$H31<>"x"),0,INDEX($Y$4:$Y$14,MATCH($G31,$X$4:$X41,0),1))*J31*1.1 -> 0 | L31: =K31*$L$2 -> 0 | M31: =IF($I31<>"x",0,INDEX($Y$27:$Y$37,MATCH($G31,$X$27:$X64,0),1))*J31*1.1 -> 0 | N31: =M31*$N$2 -> 0 | O31: =SUM(K31:N31) -> 0 | P31: =IF(OR($E31<>"CS",$H31<>"x"),0,INDEX($Z$4:$Z$14,MATCH($G31,$X$4:$X41,0),1))*J31*1.1 -> 0 | Q31: =IF($I31<>"x",0,INDEX($Z$27:$Z$37,MATCH($G31,$X$27:$X64,0),1))*J31*1.1 -> 0 | R31: =SUM(P31:Q31) -> 0 | S31: =R31+O31 -> 0 | V31: Insulation | W31: 2" thick | X31: 3 | Y31: 14 | Z31: 5
B32: =1+B31 -> 29 | C32: CW | D32: CHILLER | E32: CS | F32: 0 | G32: 0.75 | H32: x | I32: x | J32: =IF(F32="","",+$I$2*F32) -> 0 | K32: =IF(OR($E32<>"CS",$H32<>"x"),0,INDEX($Y$4:$Y$14,MATCH($G32,$X$4:$X42,0),1))*J32*1.1 -> 0 | L32: =K32*$L$2 -> 0 | M32: =IF($I32<>"x",0,INDEX($Y$27:$Y$37,MATCH($G32,$X$27:$X65,0),1))*J32*1.1 -> 0 | N32: =M32*$N$2 -> 0 | O32: =SUM(K32:N32) -> 0 | P32: =IF(OR($E32<>"CS",$H32<>"x"),0,INDEX($Z$4:$Z$14,MATCH($G32,$X$4:$X42,0),1))*J32*1.1 -> 0 | Q32: =IF($I32<>"x",0,INDEX($Z$27:$Z$37,MATCH($G32,$X$27:$X65,0),1))*J32*1.1 -> 0 | R32: =SUM(P32:Q32) -> 0 | S32: =R32+O32 -> 0 | V32: Insulation | W32: 2" thick | X32: 4 | Y32: 18 | Z32: 5
B33: =1+B32 -> 30 | C33: CW | D33: CHILLER | E33: CS | F33: 0 | G33: 0.75 | H33: x | I33: x | J33: =IF(F33="","",+$I$2*F33) -> 0 | K33: =IF(OR($E33<>"CS",$H33<>"x"),0,INDEX($Y$4:$Y$14,MATCH($G33,$X$4:$X43,0),1))*J33*1.1 -> 0 | L33: =K33*$L$2 -> 0 | M33: =IF($I33<>"x",0,INDEX($Y$27:$Y$37,MATCH($G33,$X$27:$X66,0),1))*J33*1.1 -> 0 | N33: =M33*$N$2 -> 0 | O33: =SUM(K33:N33) -> 0 | P33: =IF(OR($E33<>"CS",$H33<>"x"),0,INDEX($Z$4:$Z$14,MATCH($G33,$X$4:$X43,0),1))*J33*1.1 -> 0 | Q33: =IF($I33<>"x",0,INDEX($Z$27:$Z$37,MATCH($G33,$X$27:$X66,0),1))*J33*1.1 -> 0 | R33: =SUM(P33:Q33) -> 0 | S33: =R33+O33 -> 0 | V33: Insulation | W33: 2" thick | X33: 5 | Y33: =66/3 -> 22 | Z33: 5
B34: =1+B33 -> 31 | C34: CW | D34: CHILLER | E34: CS | F34: 0 | G34: 0.75 | H34: x | I34: x | J34: =IF(F34="","",+$I$2*F34) -> 0 | K34: =IF(OR($E34<>"CS",$H34<>"x"),0,INDEX($Y$4:$Y$14,MATCH($G34,$X$4:$X44,0),1))*J34*1.1 -> 0 | L34: =K34*$L$2 -> 0 | M34: =IF($I34<>"x",0,INDEX($Y$27:$Y$37,MATCH($G34,$X$27:$X67,0),1))*J34*1.1 -> 0 | N34: =M34*$N$2 -> 0 | O34: =SUM(K34:N34) -> 0 | P34: =IF(OR($E34<>"CS",$H34<>"x"),0,INDEX($Z$4:$Z$14,MATCH($G34,$X$4:$X44,0),1))*J34*1.1 -> 0 | Q34: =IF($I34<>"x",0,INDEX($Z$27:$Z$37,MATCH($G34,$X$27:$X67,0),1))*J34*1.1 -> 0 | R34: =SUM(P34:Q34) -> 0 | S34: =R34+O34 -> 0 | V34: Insulation | W34: 2" thick | X34: 6 | Y34: 26 | Z34: 6
B35: =1+B34 -> 32 | C35: CW | D35: CHILLER | E35: CS | F35: 0 | G35: 0.75 | H35: x | I35: x | J35: =IF(F35="","",+$I$2*F35) -> 0 | K35: =IF(OR($E35<>"CS",$H35<>"x"),0,INDEX($Y$4:$Y$14,MATCH($G35,$X$4:$X45,0),1))*J35*1.1 -> 0 | L35: =K35*$L$2 -> 0 | M35: =IF($I35<>"x",0,INDEX($Y$27:$Y$37,MATCH($G35,$X$27:$X68,0),1))*J35*1.1 -> 0 | N35: =M35*$N$2 -> 0 | O35: =SUM(K35:N35) -> 0 | P35: =IF(OR($E35<>"CS",$H35<>"x"),0,INDEX($Z$4:$Z$14,MATCH($G35,$X$4:$X45,0),1))*J35*1.1 -> 0 | Q35: =IF($I35<>"x",0,INDEX($Z$27:$Z$37,MATCH($G35,$X$27:$X68,0),1))*J35*1.1 -> 0 | R35: =SUM(P35:Q35) -> 0 | S35: =R35+O35 -> 0 | V35: Insulation | W35: 2" thick | X35: 8 | Y35: 28 | Z35: 6
